Workbook
Name Slicer_Representative: #N/A

Sheet Sheet3
A1: Data returned for call count 2, R04 (First 1000 rows).
A3: calls[Call number] | B3: calls[Customer ID] | C3: calls[Duration] | D3: calls[Representative] | E3: calls[Date of Call] | F3: calls[Purchase Amount] | G3: calls[Satisfaction Rating] | H3: calls[FY] | I3: calls[Day of week] | J3: calls[Duration Bucket] | K3: calls[Rating rounded] | L3: calls[Date of Call (Month)] | M3: calls[Date of Call (Month Index)]
A4: Call_7278 | B4: C0003 | C4: 103 | D4: R04 | E4: 44929 | F4: 148 | G4: 4.4 | H4: 2023 | I4: Tuesday | J4: 1 to 2 hours | K4: 4 | L4: Jan | M4: 1
A5: Call_7292 | B5: C0004 | C5: 38 | D5: R04 | E5: 44933 | F5: 92 | G5: 4.9 | H5: 2023 | I5: Saturday | J5: 30 to 60 mins | K5: 5 | L5: Jan | M5: 1
A6: Call_7293 | B6: C0003 | C6: 67 | D6: R04 | E6: 44934 | F6: 165 | G6: 4.5 | H6: 2023 | I6: Sunday | J6: 1 to 2 hours | K6: 5 | L6: Jan | M6: 1
A7: Call_7299 | B7: C0009 | C7: 31 | D7: R04 | E7: 44936 | F7: 123 | G7: 2.9 | H7: 2023 | I7: Tuesday | J7: 30 to 60 mins | K7: 3 | L7: Jan | M7: 1
A8: Call_7309 | B8: C0015 | C8: 81 | D8: R04 | E8: 44943 | F8: 86 | G8: 2.4 | H8: 2023 | I8: Tuesday | J8: 1 to 2 hours | K8: 2 | L8: Jan | M8: 1
A9: Call_7311 | B9: C0004 | C9: 74 | D9: R04 | E9: 44943 | F9: 96 | G9: 4.7 | H9: 2023 | I9: Tuesday | J9: 1 to 2 hours | K9: 5 | L9: Jan | M9: 1
A10: Call_7322 | B10: C0013 | C10: 100 | D10: R04 | E10: 44947 | F10: 135 | G10: 3.8 | H10: 2023 | I10: Saturday | J10: 1 to 2 hours | K10: 4 | L10: Jan | M10: 1
A11: Call_7332 | B11: C0010 | C11: 130 | D11: R04 | E11: 44950 | F11: 126 | G11: 2.5 | H11: 2023 | I11: Tuesday | J11: More than 2 hours | K11: 3 | L11: Jan | M11: 1
A12: Call_7335 | B12: C0001 | C12: 147 | D12: R04 | E12: 44951 | F12: 105 | G12: 4.4 | H12: 2023 | I12: Wednesday | J12: More than 2 hours | K12: 4 | L12: Jan | M12: 1
A13: Call_7338 | B13: C0010 | C13: 124 | D13: R04 | E13: 44953 | F13: 215 | G13: 4.1 | H13: 2023 | I13: Friday | J13: More than 2 hours | K13: 4 | L13: Jan | M13: 1
A14: Call_7351 | B14: C0010 | C14: 45 | D14: R04 | E14: 44958 | F14: 34 | G14: 3.7 | H14: 2023 | I14: Wednesday | J14: 30 to 60 mins | K14: 4 | L14: Feb | M14: 2
A15: Call_7355 | B15: C0011 | C15: 137 | D15: R04 | E15: 44958 | F15: 90 | G15: 4.1 | H15: 2023 | I15: Wednesday | J15: More than 2 hours | K15: 4 | L15: Feb | M15: 2
... A189: Call_8267 | B189: C0007 | C189: 127 | D189: R04 | E189: 45290 | F189: 215 | G189: 3.8 | H189: 2024 | I189: Saturday | J189: More than 2 hours | K189: 4 | L189: Dec | M189: 12

Sheet Sheet2
A1: Data returned for call count , R04 (First 1000 rows).
A3: calls[Call number] | B3: calls[Customer ID] | C3: calls[Duration] | D3: calls[Representative] | E3: calls[Date of Call] | F3: calls[Purchase Amount] | G3: calls[Satisfaction Rating] | H3: calls[FY] | I3: calls[Day of week] | J3: calls[Duration Bucket] | K3: calls[Rating rounded] | L3: calls[Date of Call (Month)] | M3: calls[Date of Call (Month Index)]
A4: Call_7278 | B4: C0003 | C4: 103 | D4: R04 | E4: 44929 | F4: 148 | G4: 4.4 | H4: 2023 | I4: Tuesday | J4: 1 to 2 hours | K4: 4 | L4: Jan | M4: 1
A5: Call_7292 | B5: C0004 | C5: 38 | D5: R04 | E5: 44933 | F5: 92 | G5: 4.9 | H5: 2023 | I5: Saturday | J5: 30 to 60 mins | K5: 5 | L5: Jan | M5: 1
A6: Call_7293 | B6: C0003 | C6: 67 | D6: R04 | E6: 44934 | F6: 165 | G6: 4.5 | H6: 2023 | I6: Sunday | J6: 1 to 2 hours | K6: 5 | L6: Jan | M6: 1
A7: Call_7299 | B7: C0009 | C7: 31 | D7: R04 | E7: 44936 | F7: 123 | G7: 2.9 | H7: 2023 | I7: Tuesday | J7: 30 to 60 mins | K7: 3 | L7: Jan | M7: 1
A8: Call_7309 | B8: C0015 | C8: 81 | D8: R04 | E8: 44943 | F8: 86 | G8: 2.4 | H8: 2023 | I8: Tuesday | J8: 1 to 2 hours | K8: 2 | L8: Jan | M8: 1
A9: Call_7311 | B9: C0004 | C9: 74 | D9: R04 | E9: 44943 | F9: 96 | G9: 4.7 | H9: 2023 | I9: Tuesday | J9: 1 to 2 hours | K9: 5 | L9: Jan | M9: 1
A10: Call_7322 | B10: C0013 | C10: 100 | D10: R04 | E10: 44947 | F10: 135 | G10: 3.8 | H10: 2023 | I10: Saturday | J10: 1 to 2 hours | K10: 4 | L10: Jan | M10: 1
A11: Call_7332 | B11: C0010 | C11: 130 | D11: R04 | E11: 44950 | F11: 126 | G11: 2.5 | H11: 2023 | I11: Tuesday | J11: More than 2 hours | K11: 3 | L11: Jan | M11: 1
A12: Call_7335 | B12: C0001 | C12: 147 | D12: R04 | E12: 44951 | F12: 105 | G12: 4.4 | H12: 2023 | I12: Wednesday | J12: More than 2 hours | K12: 4 | L12: Jan | M12: 1
A13: Call_7338 | B13: C0010 | C13: 124 | D13: R04 | E13: 44953 | F13: 215 | G13: 4.1 | H13: 2023 | I13: Friday | J13: More than 2 hours | K13: 4 | L13: Jan | M13: 1
A14: Call_7351 | B14: C0010 | C14: 45 | D14: R04 | E14: 44958 | F14: 34 | G14: 3.7 | H14: 2023 | I14: Wednesday | J14: 30 to 60 mins | K14: 4 | L14: Feb | M14: 2
A15: Call_7355 | B15: C0011 | C15: 137 | D15: R04 | E15: 44958 | F15: 90 | G15: 4.1 | H15: 2023 | I15: Wednesday | J15: More than 2 hours | K15: 4 | L15: Feb | M15: 2
... A189: Call_8267 | B189: C0007 | C189: 127 | D189: R04 | E189: 45290 | F189: 215 | G189: 3.8 | H189: 2024 | I189: Saturday | J189: More than 2 hours | K189: 4 | L189: Dec | M189: 12

Sheet Sheet1
A3: call count | B3: Total Amount | C3: Total Duration | D3: Avg. Rating | E3: 5* calls
A4: 1000 | B4: 96623 | C4: 89850 | D4: 3.8854 | E4: 307
A9: call count | B9: Total Amount | C9: Total Duration | D9: Avg. Rating | E9: 5* calls
A10: 200 | B10: 20104 | C10: 18209 | D10: 3.8825 | E10: 51
A15: Row Labels | B15: call count | C15: call count 2
A16: Jan | B16: 21 | C16: 21
A17: Feb | B17: 18 | C17: 18 | F17: Row Labels | G17: call count
A18: Mar | B18: 31 | C18: 31 | F18: Sunday | G18: 27
A19: Apr | B19: 20 | C19: 20 | F19: Monday | G19: 22
A20: May | B20: 8 | C20: 8 | F20: Tuesday | G20: 27
A21: Jun | B21: 12 | C21: 12 | F21: Wednesday | G21: 27
A22: Jul | B22: 12 | C22: 12 | F22: Thursday | G22: 27
A23: Aug | B23: 7 | C23: 7 | F23: Friday | G23: 32
A24: Sep | B24: 20 | C24: 20 | F24: Saturday | G24: 38
A25: Oct | B25: 24 | C25: 24 | F25: Grand Total | G25: 200
A26: Nov | B26: 12 | C26: 12
A27: Dec | B27: 15 | C27: 15
A28: Grand Total | B28: 200 | C28: 200
G30: for graph | J30: se;ected rep | K30: =A46 -> R05
G33: Rep | H33: Calls | I33: Amount | J33: Sel. Calls | K33: Sel. Amount
A34: Row Labels | B34: call count | C34: Total Amount | G34: {=A35:C39} -> R01 | H34: 189 | I34: 18415 | J34: =IF(G34=$K$30,H34,NA()) -> #N/A | K34: =IF(G34=$K$30,I34,NA()) -> #N/A
A35: R01 | B35: 189 | C35: 18415 | G35: R02 | H35: 218 | I35: 20581 | J35: =IF(G35=$K$30,H35,NA()) -> #N/A | K35: =IF(G35=$K$30,I35,NA()) -> #N/A
A36: R02 | B36: 218 | C36: 20581 | G36: R03 | H36: 207 | I36: 20872 | J36: =IF(G36=$K$30,H36,NA()) -> #N/A | K36: =IF(G36=$K$30,I36,NA()) -> #N/A
A37: R03 | B37: 207 | C37: 20872 | G37: R04 | H37: 186 | I37: 16651 | J37: =IF(G37=$K$30,H37,NA()) -> #N/A | K37: =IF(G37=$K$30,I37,NA()) -> #N/A
A38: R04 | B38: 186 | C38: 16651 | G38: R05 | H38: 200 | I38: 20104 | J38: =IF(G38=$K$30,H38,NA()) -> 200 | K38: =IF(G38=$K$30,I38,NA()) -> 20104
A39: R05 | B39: 200 | C39: 20104
A40: Grand Total | B40: 1000 | C40: 96623
G44: rep summary
A45: Row Labels
A46: R05 | G46: % of calls | H46: =A10/A4 -> 0.2
G47: calls | H47: =_xlfn.XLOOKUP(A46,G34:G38,H34:H38) -> 200
G48: amount | H48: =_xlfn.XLOOKUP(A46,G34:G38,I34:I38) -> 20104
G50: call rank | H50: =_xlfn.RANK.AVG(H47,H34:H38) -> 3
G51: amount rank | H51: =_xlfn.RANK.AVG(H48,I34:I38) -> 3
K52: call count | L52: Column Labels
K53: Row Labels | L53: Female | M53: Male | N53: Grand Total
G54: labels | K54: Cincinnati | L54: 144 | M54: 132 | N54: 276
K55: Cleveland | L55: 326 | M55: 63 | N55: 389
H56: ="% of calls:"&TEXT(H46,"0%") -> % of calls:20% | K56: Columbus | L56: 129 | M56: 206 | N56: 335
H57: =IF(COUNTA(A46:A51)>1,"","Call rank:"&H50) -> Call rank:3 | K57: Grand Total | L57: 599 | M57: 401 | N57: 1000
...

Sheet customer report
C1: Call Center Report
R25: {=Sheet1!B69:F69} -> R01 | S25: R02 | T25: R03 | U25: R04 | V25: R05 | W25: TOTAL
Q26: {=IF(Sheet1!A95:G112="","",Sheet1!A95:G112)} -> Cincinnati
Q27: C0003 | R27: 891 | S27: 1332 | T27: 1282 | U27: 739 | V27: 560 | W27: 4804
Q28: C0004 | R28: 1991 | S28: 1886 | T28: 1206 | U28: 884 | V28: 1722 | W28: 7689
Q29: C0011 | R29: 1163 | S29: 1180 | T29: 1616 | U29: 1043 | V29: 1747 | W29: 6749
Q30: C0012 | R30: 1438 | S30: 1616 | T30: 866 | U30: 829 | V30: 2070 | W30: 6819
Q31: Cleveland
Q32: C0002 | R32: 1233 | S32: 223 | T32: 1680 | U32: 990 | V32: 1508 | W32: 5634
Q33: C0007 | R33: 1598 | S33: 1907 | T33: 869 | U33: 1426 | V33: 1416 | W33: 7216
Q34: C0008 | R34: 900 | S34: 1016 | T34: 960 | U34: 940 | V34: 1193 | W34: 5009
N35: =Sheet1!H56 -> % of calls:20% | Q35: C0010 | R35: 900 | S35: 1470 | T35: 1617 | U35: 1314 | V35: 941 | W35: 6242
N36: =Sheet1!H57 -> Call rank:3 | Q36: C0013 | R36: 1255 | S36: 516 | T36: 1874 | U36: 1863 | V36: 1722 | W36: 7230
N37: =Sheet1!H58 -> Amount rank:3 | Q37: C0015 | R37: 1138 | S37: 1898 | T37: 1482 | U37: 846 | V37: 1154 | W37: 6518
Q38: Columbus
Q39: C0001 | R39: 1655 | S39: 805 | T39: 2263 | U39: 987 | V39: 1075 | W39: 6785
Q40: C0005 | R40: 1104 | S40: 2280 | T40: 1445 | U40: 1722 | V40: 1196 | W40: 7747
Q41: C0006 | R41: 372 | S41: 1818 | T41: 1346 | U41: 1156 | V41: 1484 | W41: 6176
Q42: C0009 | R42: 1415 | S42: 1271 | T42: 1214 | U42: 1135 | V42: 1566 | W42: 6601
Q43: C0014 | R43: 1362 | S43: 1363 | T43: 1152 | U43: 777 | V43: 750 | W43: 5404

Sheet Data
B1: Call Centre Data
B3: Call number | C3: Customer ID | D3: Duration | E3: Representative | F3: Date of Call | G3: Purchase Amount | H3: Satisfaction Rating | I3: FY | J3: Day of week | K3: Duration Bucket | L3: Rating rounded | Q3: Customer ID | R3: Gedner | S3: Age | T3: City
B4: Call_7271 | C4: C0003 | D4: 116 | E4: R05 | F4: 44927 | G4: 128 | H4: 4.9 | I4: =IF(MONTH(calls[[#This Row],[Date of Call]])<=6, YEAR(calls[[#This Row],[Date of Call]]), YEAR(calls[[#This Row],[Date of Call]])+1) -> 2023 | J4: =TEXT(calls[[#This Row],[Date of Call]],"DDDD") -> Sunday | K4: {=_xlfn.IFS(calls[[#This Row],[Duration]]<=10,"Under 10 mins", calls[[#This Row],[Duration]]<=30, "10 to 30 mins", calls[[#This Row],[Duration]]<=60, "30 to 60 mins", calls[[#This Row],[Duration]]<=120, "1 to 2 hours", TRUE, "More than 2 hours")} -> 1 to 2 hours | L4: =ROUND(calls[[#This Row],[Satisfaction Rating]],0) -> 5 | Q4: C0001 | R4: Male | S4: 41 | T4: Columbus
B5: Call_7272 | C5: C0004 | D5: 119 | E5: R05 | F5: 44927 | G5: 135 | H5: 2.9 | I5: =IF(MONTH(calls[[#This Row],[Date of Call]])<=6, YEAR(calls[[#This Row],[Date of Call]]), YEAR(calls[[#This Row],[Date of Call]])+1) -> 2023 | J5: =TEXT(calls[[#This Row],[Date of Call]],"DDDD") -> Sunday | K5: {=_xlfn.IFS(calls[[#This Row],[Duration]]<=10,"Under 10 mins", calls[[#This Row],[Duration]]<=30, "10 to 30 mins", calls[[#This Row],[Duration]]<=60, "30 to 60 mins", calls[[#This Row],[Duration]]<=120, "1 to 2 hours", TRUE, "More than 2 hours")} -> 1 to 2 hours | L5: =ROUND(calls[[#This Row],[Satisfaction Rating]],0) -> 3 | Q5: C0002 | R5: Male | S5: 31 | T5: Cleveland
B6: Call_7273 | C6: C0005 | D6: 68 | E6: R02 | F6: 44927 | G6: 66 | H6: 4.7 | I6: =IF(MONTH(calls[[#This Row],[Date of Call]])<=6, YEAR(calls[[#This Row],[Date of Call]]), YEAR(calls[[#This Row],[Date of Call]])+1) -> 2023 | J6: =TEXT(calls[[#This Row],[Date of Call]],"DDDD") -> Sunday | K6: {=_xlfn.IFS(calls[[#This Row],[Duration]]<=10,"Under 10 mins", calls[[#This Row],[Duration]]<=30, "10 to 30 mins", calls[[#This Row],[Duration]]<=60, "30 to 60 mins", calls[[#This Row],[Duration]]<=120, "1 to 2 hours", TRUE, "More than 2 hours")} -> 1 to 2 hours | L6: =ROUND(calls[[#This Row],[Satisfaction Rating]],0) -> 5 | Q6: C0003 | R6: Male | S6: 26 | T6: Cincinnati
B7: Call_7274 | C7: C0014 | D7: 119 | E7: R02 | F7: 44927 | G7: 22 | H7: 2.9 | I7: =IF(MONTH(calls[[#This Row],[Date of Call]])<=6, YEAR(calls[[#This Row],[Date of Call]]), YEAR(calls[[#This Row],[Date of Call]])+1) -> 2023 | J7: =TEXT(calls[[#This Row],[Date of Call]],"DDDD") -> Sunday | K7: {=_xlfn.IFS(calls[[#This Row],[Duration]]<=10,"Under 10 mins", calls[[#This Row],[Duration]]<=30, "10 to 30 mins", calls[[#This Row],[Duration]]<=60, "30 to 60 mins", calls[[#This Row],[Duration]]<=120, "1 to 2 hours", TRUE, "More than 2 hours")} -> 1 to 2 hours | L7: =ROUND(calls[[#This Row],[Satisfaction Rating]],0) -> 3 | Q7: C0004 | R7: Male | S7: 36 | T7: Cincinnati
B8: Call_7275 | C8: C0011 | D8: 128 | E8: R01 | F8: 44928 | G8: 31 | H8: 2.8 | I8: =IF(MONTH(calls[[#This Row],[Date of Call]])<=6, YEAR(calls[[#This Row],[Date of Call]]), YEAR(calls[[#This Row],[Date of Call]])+1) -> 2023 | J8: =TEXT(calls[[#This Row],[Date of Call]],"DDDD") -> Monday | K8: {=_xlfn.IFS(calls[[#This Row],[Duration]]<=10,"Under 10 mins", calls[[#This Row],[Duration]]<=30, "10 to 30 mins", calls[[#This Row],[Duration]]<=60, "30 to 60 mins", calls[[#This Row],[Duration]]<=120, "1 to 2 hours", TRUE, "More than 2 hours")} -> More than 2 hours | L8: =ROUND(calls[[#This Row],[Satisfaction Rating]],0) -> 3 | Q8: C0005 | R8: Male | S8: 37 | T8: Columbus
B9: Call_7276 | C9: C0011 | D9: 49 | E9: R02 | F9: 44929 | G9: 135 | H9: 4.8 | I9: =IF(MONTH(calls[[#This Row],[Date of Call]])<=6, YEAR(calls[[#This Row],[Date of Call]]), YEAR(calls[[#This Row],[Date of Call]])+1) -> 2023 | J9: =TEXT(calls[[#This Row],[Date of Call]],"DDDD") -> Tuesday | K9: {=_xlfn.IFS(calls[[#This Row],[Duration]]<=10,"Under 10 mins", calls[[#This Row],[Duration]]<=30, "10 to 30 mins", calls[[#This Row],[Duration]]<=60, "30 to 60 mins", calls[[#This Row],[Duration]]<=120, "1 to 2 hours", TRUE, "More than 2 hours")} -> 30 to 60 mins | L9: =ROUND(calls[[#This Row],[Satisfaction Rating]],0) -> 5 | Q9: C0006 | R9: Male | S9: 23 | T9: Columbus
B10: Call_7277 | C10: C0007 | D10: 84 | E10: R05 | F10: 44929 | G10: 60 | H10: 4.7 | I10: =IF(MONTH(calls[[#This Row],[Date of Call]])<=6, YEAR(calls[[#This Row],[Date of Call]]), YEAR(calls[[#This Row],[Date of Call]])+1) -> 2023 | J10: =TEXT(calls[[#This Row],[Date of Call]],"DDDD") -> Tuesday | K10: {=_xlfn.IFS(calls[[#This Row],[Duration]]<=10,"Under 10 mins", calls[[#This Row],[Duration]]<=30, "10 to 30 mins", calls[[#This Row],[Duration]]<=60, "30 to 60 mins", calls[[#This Row],[Duration]]<=120, "1 to 2 hours", TRUE, "More than 2 hours")} -> 1 to 2 hours | L10: =ROUND(calls[[#This Row],[Satisfaction Rating]],0) -> 5 | Q10: C0007 | R10: Female | S10: 22 | T10: Cleveland
B11: Call_7278 | C11: C0003 | D11: 103 | E11: R04 | F11: 44929 | G11: 148 | H11: 4.4 | I11: =IF(MONTH(calls[[#This Row],[Date of Call]])<=6, YEAR(calls[[#This Row],[Date of Call]]), YEAR(calls[[#This Row],[Date of Call]])+1) -> 2023 | J11: =TEXT(calls[[#This Row],[Date of Call]],"DDDD") -> Tuesday | K11: {=_xlfn.IFS(calls[[#This Row],[Duration]]<=10,"Under 10 mins", calls[[#This Row],[Duration]]<=30, "10 to 30 mins", calls[[#This Row],[Duration]]<=60, "30 to 60 mins", calls[[#This Row],[Duration]]<=120, "1 to 2 hours", TRUE, "More than 2 hours")} -> 1 to 2 hours | L11: =ROUND(calls[[#This Row],[Satisfaction Rating]],0) -> 4 | Q11: C0008 | R11: Female | S11: 42 | T11: Cleveland
B12: Call_7279 | C12: C0005 | D12: 31 | E12: R02 | F12: 44929 | G12: 135 | H12: 3.6 | I12: =IF(MONTH(calls[[#This Row],[Date of Call]])<=6, YEAR(calls[[#This Row],[Date of Call]]), YEAR(calls[[#This Row],[Date of Call]])+1) -> 2023 | J12: =TEXT(calls[[#This Row],[Date of Call]],"DDDD") -> Tuesday | K12: {=_xlfn.IFS(calls[[#This Row],[Duration]]<=10,"Under 10 mins", calls[[#This Row],[Duration]]<=30, "10 to 30 mins", calls[[#This Row],[Duration]]<=60, "30 to 60 mins", calls[[#This Row],[Duration]]<=120, "1 to 2 hours", TRUE, "More than 2 hours")} -> 30 to 60 mins | L12: =ROUND(calls[[#This Row],[Satisfaction Rating]],0) -> 4 | Q12: C0009 | R12: Female | S12: 25 | T12: Columbus
B13: Call_7280 | C13: C0010 | D13: 44 | E13: R03 | F13: 44929 | G13: 105 | H13: 2.9 | I13: =IF(MONTH(calls[[#This Row],[Date of Call]])<=6, YEAR(calls[[#This Row],[Date of Call]]), YEAR(calls[[#This Row],[Date of Call]])+1) -> 2023 | J13: =TEXT(calls[[#This Row],[Date of Call]],"DDDD") -> Tuesday | K13: {=_xlfn.IFS(calls[[#This Row],[Duration]]<=10,"Under 10 mins", calls[[#This Row],[Duration]]<=30, "10 to 30 mins", calls[[#This Row],[Duration]]<=60, "30 to 60 mins", calls[[#This Row],[Duration]]<=120, "1 to 2 hours", TRUE, "More than 2 hours")} -> 30 to 60 mins | L13: =ROUND(calls[[#This Row],[Satisfaction Rating]],0) -> 3 | Q13: C0010 | R13: Female | S13: 30 | T13: Cleveland
B14: Call_7281 | C14: C0011 | D14: 102 | E14: R02 | F14: 44929 | G14: 69 | H14: 4.9 | I14: =IF(MONTH(calls[[#This Row],[Date of Call]])<=6, YEAR(calls[[#This Row],[Date of Call]]), YEAR(calls[[#This Row],[Date of Call]])+1) -> 2023 | J14: =TEXT(calls[[#This Row],[Date of Call]],"DDDD") -> Tuesday | K14: {=_xlfn.IFS(calls[[#This Row],[Duration]]<=10,"Under 10 mins", calls[[#This Row],[Duration]]<=30, "10 to 30 mins", calls[[#This Row],[Duration]]<=60, "30 to 60 mins", calls[[#This Row],[Duration]]<=120, "1 to 2 hours", TRUE, "More than 2 hours")} -> 1 to 2 hours | L14: =ROUND(calls[[#This Row],[Satisfaction Rating]],0) -> 5 | Q14: C0011 | R14: Female | S14: 30 | T14: Cincinnati
B15: Call_7282 | C15: C0013 | D15: 135 | E15: R05 | F15: 44929 | G15: 46 | H15: 3.4 | I15: =IF(MONTH(calls[[#This Row],[Date of Call]])<=6, YEAR(calls[[#This Row],[Date of Call]]), YEAR(calls[[#This Row],[Date of Call]])+1) -> 2023 | J15: =TEXT(calls[[#This Row],[Date of Call]],"DDDD") -> Tuesday | K15: {=_xlfn.IFS(calls[[#This Row],[Duration]]<=10,"Under 10 mins", calls[[#This Row],[Duration]]<=30, "10 to 30 mins", calls[[#This Row],[Duration]]<=60, "30 to 60 mins", calls[[#This Row],[Duration]]<=120, "1 to 2 hours", TRUE, "More than 2 hours")} -> More than 2 hours | L15: =ROUND(calls[[#This Row],[Satisfaction Rating]],0) -> 3 | Q15: C0012 | R15: Female | S15: 28 | T15: Cincinnati
... B18: Call_7285 | C18: C0013 | D18: 48 | E18: R01 | F18: 44930 | G18: 68 | H18: 4.9 | I18: =IF(MONTH(calls[[#This Row],[Date of Call]])<=6, YEAR(calls[[#This Row],[Date of Call]]), YEAR(calls[[#This Row],[Date of Call]])+1) -> 2023 | J18: =TEXT(calls[[#This Row],[Date of Call]],"DDDD") -> Wednesday | K18: {=_xlfn.IFS(calls[[#This Row],[Duration]]<=10,"Under 10 mins", calls[[#This Row],[Duration]]<=30, "10 to 30 mins", calls[[#This Row],[Duration]]<=60, "30 to 60 mins", calls[[#This Row],[Duration]]<=120, "1 to 2 hours", TRUE, "More than 2 hours")} -> 30 to 60 mins | L18: =ROUND(calls[[#This Row],[Satisfaction Rating]],0) -> 5 | Q18: C0015 | R18: Female | S18: 43 | T18: Cleveland
B19: Call_7286 | C19: C0010 | D19: 176 | E19: R05 | F19: 44931 | G19: 24 | H19: 4.8 | I19: =IF(MONTH(calls[[#This Row],[Date of Call]])<=6, YEAR(calls[[#This Row],[Date of Call]]), YEAR(calls[[#This Row],[Date of Call]])+1) -> 2023 | J19: =TEXT(calls[[#This Row],[Date of Call]],"DDDD") -> Thursday | K19: {=_xlfn.IFS(calls[[#This Row],[Duration]]<=10,"Under 10 mins", calls[[#This Row],[Duration]]<=30, "10 to 30 mins", calls[[#This Row],[Duration]]<=60, "30 to 60 mins", calls[[#This Row],[Duration]]<=120, "1 to 2 hours", TRUE, "More than 2 hours")} -> More than 2 hours | L19: =ROUND(calls[[#This Row],[Satisfaction Rating]],0) -> 5
B20: Call_7287 | C20: C0010 | D20: 99 | E20: R01 | F20: 44931 | G20: 195 | H20: 3.9 | I20: =IF(MONTH(calls[[#This Row],[Date of Call]])<=6, YEAR(calls[[#This Row],[Date of Call]]), YEAR(calls[[#This Row],[Date of Call]])+1) -> 2023 | J20: =TEXT(calls[[#This Row],[Date of Call]],"DDDD") -> Thursday | K20: {=_xlfn.IFS(calls[[#This Row],[Duration]]<=10,"Under 10 mins", calls[[#This Row],[Duration]]<=30, "10 to 30 mins", calls[[#This Row],[Duration]]<=60, "30 to 60 mins", calls[[#This Row],[Duration]]<=120, "1 to 2 hours", TRUE, "More than 2 hours")} -> 1 to 2 hours | L20: =ROUND(calls[[#This Row],[Satisfaction Rating]],0) -> 4
B21: Call_7288 | C21: C0009 | D21: 28 | E21: R03 | F21: 44931 | G21: 28 | H21: 3.8 | I21: =IF(MONTH(calls[[#This Row],[Date of Call]])<=6, YEAR(calls[[#This Row],[Date of Call]]), YEAR(calls[[#This Row],[Date of Call]])+1) -> 2023 | J21: =TEXT(calls[[#This Row],[Date of Call]],"DDDD") -> Thursday | K21: {=_xlfn.IFS(calls[[#This Row],[Duration]]<=10,"Under 10 mins", calls[[#This Row],[Duration]]<=30, "10 to 30 mins", calls[[#This Row],[Duration]]<=60, "30 to 60 mins", calls[[#This Row],[Duration]]<=120, "1 to 2 hours", TRUE, "More than 2 hours")} -> 10 to 30 mins | L21: =ROUND(calls[[#This Row],[Satisfaction Rating]],0) -> 4
B22: Call_7289 | C22: C0007 | D22: 54 | E22: R02 | F22: 44931 | G22: 170 | H22: 4.3 | I22: =IF(MONTH(calls[[#This Row],[Date of Call]])<=6, YEAR(calls[[#This Row],[Date of Call]]), YEAR(calls[[#This Row],[Date of Call]])+1) -> 2023 | J22: =TEXT(calls[[#This Row],[Date of Call]],"DDDD") -> Thursday | K22: {=_xlfn.IFS(calls[[#This Row],[Duration]]<=10,"Under 10 mins", calls[[#This Row],[Duration]]<=30, "10 to 30 mins", calls[[#This Row],[Duration]]<=60, "30 to 60 mins", calls[[#This Row],[Duration]]<=120, "1 to 2 hours", TRUE, "More than 2 hours")} -> 30 to 60 mins | L22: =ROUND(calls[[#This Row],[Satisfaction Rating]],0) -> 4
B23: Call_7290 | C23: C0006 | D23: 48 | E23: R05 | F23: 44932 | G23: 30 | H23: 4.4 | I23: =IF(MONTH(calls[[#This Row],[Date of Call]])<=6, YEAR(calls[[#This Row],[Date of Call]]), YEAR(calls[[#This Row],[Date of Call]])+1) -> 2023 | J23: =TEXT(calls[[#This Row],[Date of Call]],"DDDD") -> Friday | K23: {=_xlfn.IFS(calls[[#This Row],[Duration]]<=10,"Under 10 mins", calls[[#This Row],[Duration]]<=30, "10 to 30 mins", calls[[#This Row],[Duration]]<=60, "30 to 60 mins", calls[[#This Row],[Duration]]<=120, "1 to 2 hours", TRUE, "More than 2 hours")} -> 30 to 60 mins | L23: =ROUND(calls[[#This Row],[Satisfaction Rating]],0) -> 4
B24: Call_7291 | C24: C0004 | D24: 128 | E24: R05 | F24: 44932 | G24: 72 | H24: 5 | I24: =IF(MONTH(calls[[#This Row],[Date of Call]])<=6, YEAR(calls[[#This Row],[Date of Call]]), YEAR(calls[[#This Row],[Date of Call]])+1) -> 2023 | J24: =TEXT(calls[[#This Row],[Date of Call]],"DDDD") -> Friday | K24: {=_xlfn.IFS(calls[[#This Row],[Duration]]<=10,"Under 10 mins", calls[[#This Row],[Duration]]<=30, "10 to 30 mins", calls[[#This Row],[Duration]]<=60, "30 to 60 mins", calls[[#This Row],[Duration]]<=120, "1 to 2 hours", TRUE, "More than 2 hours")} -> More than 2 hours | L24: =ROUND(calls[[#This Row],[Satisfaction Rating]],0) -> 5
B25: Call_7292 | C25: C0004 | D25: 38 | E25: R04 | F25: 44933 | G25: 92 | H25: 4.9 | I25: =IF(MONTH(calls[[#This Row],[Date of Call]])<=6, YEAR(calls[[#This Row],[Date of Call]]), YEAR(calls[[#This Row],[Date of Call]])+1) -> 2023 | J25: =TEXT(calls[[#This Row],[Date of Call]],"DDDD") -> Saturday | K25: {=_xlfn.IFS(calls[[#This Row],[Duration]]<=10,"Under 10 mins", calls[[#This Row],[Duration]]<=30, "10 to 30 mins", calls[[#This Row],[Duration]]<=60, "30 to 60 mins", calls[[#This Row],[Duration]]<=120, "1 to 2 hours", TRUE, "More than 2 hours")} -> 30 to 60 mins | L25: =ROUND(calls[[#This Row],[Satisfaction Rating]],0) -> 5
B26: Call_7293 | C26: C0003 | D26: 67 | E26: R04 | F26: 44934 | G26: 165 | H26: 4.5 | I26: =IF(MONTH(calls[[#This Row],[Date of Call]])<=6, YEAR(calls[[#This Row],[Date of Call]]), YEAR(calls[[#This Row],[Date of Call]])+1) -> 2023 | J26: =TEXT(calls[[#This Row],[Date of Call]],"DDDD") -> Sunday | K26: {=_xlfn.IFS(calls[[#This Row],[Duration]]<=10,"Under 10 mins", calls[[#This Row],[Duration]]<=30, "10 to 30 mins", calls[[#This Row],[Duration]]<=60, "30 to 60 mins", calls[[#This Row],[Duration]]<=120, "1 to 2 hours", TRUE, "More than 2 hours")} -> 1 to 2 hours | L26: =ROUND(calls[[#This Row],[Satisfaction Rating]],0) -> 5
B27: Call_7294 | C27: C0015 | D27: 58 | E27: R02 | F27: 44934 | G27: 140 | H27: 2.1 | I27: =IF(MONTH(calls[[#This Row],[Date of Call]])<=6, YEAR(calls[[#This Row],[Date of Call]]), YEAR(calls[[#This Row],[Date of Call]])+1) -> 2023 | J27: =TEXT(calls[[#This Row],[Date of Call]],"DDDD") -> Sunday | K27: {=_xlfn.IFS(calls[[#This Row],[Duration]]<=10,"Under 10 mins", calls[[#This Row],[Duration]]<=30, "10 to 30 mins", calls[[#This Row],[Duration]]<=60, "30 to 60 mins", calls[[#This Row],[Duration]]<=120, "1 to 2 hours", TRUE, "More than 2 hours")} -> 30 to 60 mins | L27: =ROUND(calls[[#This Row],[Satisfaction Rating]],0) -> 2
B28: Call_7295 | C28: C0010 | D28: 54 | E28: R01 | F28: 44934 | G28: 111 | H28: 3.3 | I28: =IF(MONTH(calls[[#This Row],[Date of Call]])<=6, YEAR(calls[[#This Row],[Date of Call]]), YEAR(calls[[#This Row],[Date of Call]])+1) -> 2023 | J28: =TEXT(calls[[#This Row],[Date of Call]],"DDDD") -> Sunday | K28: {=_xlfn.IFS(calls[[#This Row],[Duration]]<=10,"Under 10 mins", calls[[#This Row],[Duration]]<=30, "10 to 30 mins", calls[[#This Row],[Duration]]<=60, "30 to 60 mins", calls[[#This Row],[Duration]]<=120, "1 to 2 hours", TRUE, "More than 2 hours")} -> 30 to 60 mins | L28: =ROUND(calls[[#This Row],[Satisfaction Rating]],0) -> 3
B29: Call_7296 | C29: C0012 | D29: 28 | E29: R05 | F29: 44935 | G29: 63 | H29: 4.1 | I29: =IF(MONTH(calls[[#This Row],[Date of Call]])<=6, YEAR(calls[[#This Row],[Date of Call]]), YEAR(calls[[#This Row],[Date of Call]])+1) -> 2023 | J29: =TEXT(calls[[#This Row],[Date of Call]],"DDDD") -> Monday | K29: {=_xlfn.IFS(calls[[#This Row],[Duration]]<=10,"Under 10 mins", calls[[#This Row],[Duration]]<=30, "10 to 30 mins", calls[[#This Row],[Duration]]<=60, "30 to 60 mins", calls[[#This Row],[Duration]]<=120, "1 to 2 hours", TRUE, "More than 2 hours")} -> 10 to 30 mins | L29: =ROUND(calls[[#This Row],[Satisfaction Rating]],0) -> 4
B30: Call_7297 | C30: C0002 | D30: 73 | E30: R05 | F30: 44935 | G30: 80 | H30: 4.2 | I30: =IF(MONTH(calls[[#This Row],[Date of Call]])<=6, YEAR(calls[[#This Row],[Date of Call]]), YEAR(calls[[#This Row],[Date of Call]])+1) -> 2023 | J30: =TEXT(calls[[#This Row],[Date of Call]],"DDDD") -> Monday | K30: {=_xlfn.IFS(calls[[#This Row],[Duration]]<=10,"Under 10 mins", calls[[#This Row],[Duration]]<=30, "10 to 30 mins", calls[[#This Row],[Duration]]<=60, "30 to 60 mins", calls[[#This Row],[Duration]]<=120, "1 to 2 hours", TRUE, "More than 2 hours")} -> 1 to 2 hours | L30: =ROUND(calls[[#This Row],[Satisfaction Rating]],0) -> 4
... B1003: Call_8270 | C1003: C0009 | D1003: 114 | E1003: R01 | F1003: 45291 | G1003: 40 | H1003: 3.9 | I1003: =IF(MONTH(calls[[#This Row],[Date of Call]])<=6, YEAR(calls[[#This Row],[Date of Call]]), YEAR(calls[[#This Row],[Date of Call]])+1) -> 2024 | J1003: =TEXT(calls[[#This Row],[Date of Call]],"DDDD") -> Sunday | K1003: {=_xlfn.IFS(calls[[#This Row],[Duration]]<=10,"Under 10 mins", calls[[#This Row],[Duration]]<=30, "10 to 30 mins", calls[[#This Row],[Duration]]<=60, "30 to 60 mins", calls[[#This Row],[Duration]]<=120, "1 to 2 hours", TRUE, "More than 2 hours")} -> 1 to 2 hours | L1003: =ROUND(calls[[#This Row],[Satisfaction Rating]],0) -> 4

Sheet Assets
E2: Rep ID | F2: Rep Image | G2: rep image
E3: R01 | F3: #VALUE!
E4: R02 | F4: #VALUE!
E5: R03 | F5: #VALUE!
E6: R04 | F6: #VALUE!
E7: R05 | F7: #VALUE!
